ERROR 2018-11-26 15:46:05,543 /Library/Frameworks/Python.framework/Versions/3.6/lib/python3.6/site-packages/django/core/handlers/exception.py exception.py exception handle_uncaught_exception 118: Internal Server Error: /
Traceback (most recent call last):
  File "/Library/Frameworks/Python.framework/Versions/3.6/lib/python3.6/site-packages/django/template/backends/django.py", line 61, in render
    return self.template.render(context)
  File "/Library/Frameworks/Python.framework/Versions/3.6/lib/python3.6/site-packages/django/template/base.py", line 175, in render
    return self._render(context)
  File "/Library/Frameworks/Python.framework/Versions/3.6/lib/python3.6/site-packages/django/template/base.py", line 167, in _render
    return self.nodelist.render(context)
  File "/Library/Frameworks/Python.framework/Versions/3.6/lib/python3.6/site-packages/django/template/base.py", line 943, in render
    bit = node.render_annotated(context)
  File "/Library/Frameworks/Python.framework/Versions/3.6/lib/python3.6/site-packages/django/template/base.py", line 910, in render_annotated
    return self.render(context)
  File "/Library/Frameworks/Python.framework/Versions/3.6/lib/python3.6/site-packages/django/template/loader_tags.py", line 132, in render
    compiled_parent = self.get_parent(context)
  File "/Library/Frameworks/Python.framework/Versions/3.6/lib/python3.6/site-packages/django/template/loader_tags.py", line 129, in get_parent
    return self.find_template(parent, context)
  File "/Library/Frameworks/Python.framework/Versions/3.6/lib/python3.6/site-packages/django/template/loader_tags.py", line 109, in find_template
    template_name, skip=history,
  File "/Library/Frameworks/Python.framework/Versions/3.6/lib/python3.6/site-packages/django/template/engine.py", line 130, in find_template
    raise TemplateDoesNotExist(name, tried=tried)
django.template.exceptions.TemplateDoesNotExist: base.html

The above exception was the direct cause of the following exception:

Traceback (most recent call last):
  File "/Library/Frameworks/Python.framework/Versions/3.6/lib/python3.6/site-packages/django/core/handlers/exception.py", line 35, in inner
    response = get_response(request)
  File "/Library/Frameworks/Python.framework/Versions/3.6/lib/python3.6/site-packages/django/core/handlers/base.py", line 128, in _get_response
    response = self.process_exception_by_middleware(e, request)
  File "/Library/Frameworks/Python.framework/Versions/3.6/lib/python3.6/site-packages/django/core/handlers/base.py", line 126, in _get_response
    response = wrapped_callback(request, *callback_args, **callback_kwargs)
  File "/Users/DengJ/Uranus/Work/WebDesign/Buybuybuy/super/views.py", line 26, in index
    return render(request,'super/index.html',locals())
  File "/Library/Frameworks/Python.framework/Versions/3.6/lib/python3.6/site-packages/django/shortcuts.py", line 36, in render
    content = loader.render_to_string(template_name, context, request, using=using)
  File "/Library/Frameworks/Python.framework/Versions/3.6/lib/python3.6/site-packages/django/template/loader.py", line 62, in render_to_string
    return template.render(context, request)
  File "/Library/Frameworks/Python.framework/Versions/3.6/lib/python3.6/site-packages/django/template/backends/django.py", line 63, in render
    reraise(exc, self.backend)
  File "/Library/Frameworks/Python.framework/Versions/3.6/lib/python3.6/site-packages/django/template/backends/django.py", line 84, in reraise
    raise new from exc
django.template.exceptions.TemplateDoesNotExist: base.html
ERROR 2018-11-26 15:46:05,707 /Library/Frameworks/Python.framework/Versions/3.6/lib/python3.6/site-packages/django/core/servers/basehttp.py basehttp.py basehttp log_message 124: "GET / HTTP/1.1" 500 124099
ERROR 2018-11-26 15:46:44,215 /Library/Frameworks/Python.framework/Versions/3.6/lib/python3.6/site-packages/django/core/handlers/exception.py exception.py exception handle_uncaught_exception 118: Internal Server Error: /index
Traceback (most recent call last):
  File "/Library/Frameworks/Python.framework/Versions/3.6/lib/python3.6/site-packages/django/template/backends/django.py", line 61, in render
    return self.template.render(context)
  File "/Library/Frameworks/Python.framework/Versions/3.6/lib/python3.6/site-packages/django/template/base.py", line 175, in render
    return self._render(context)
  File "/Library/Frameworks/Python.framework/Versions/3.6/lib/python3.6/site-packages/django/template/base.py", line 167, in _render
    return self.nodelist.render(context)
  File "/Library/Frameworks/Python.framework/Versions/3.6/lib/python3.6/site-packages/django/template/base.py", line 943, in render
    bit = node.render_annotated(context)
  File "/Library/Frameworks/Python.framework/Versions/3.6/lib/python3.6/site-packages/django/template/base.py", line 910, in render_annotated
    return self.render(context)
  File "/Library/Frameworks/Python.framework/Versions/3.6/lib/python3.6/site-packages/django/template/loader_tags.py", line 132, in render
    compiled_parent = self.get_parent(context)
  File "/Library/Frameworks/Python.framework/Versions/3.6/lib/python3.6/site-packages/django/template/loader_tags.py", line 129, in get_parent
    return self.find_template(parent, context)
  File "/Library/Frameworks/Python.framework/Versions/3.6/lib/python3.6/site-packages/django/template/loader_tags.py", line 109, in find_template
    template_name, skip=history,
  File "/Library/Frameworks/Python.framework/Versions/3.6/lib/python3.6/site-packages/django/template/engine.py", line 130, in find_template
    raise TemplateDoesNotExist(name, tried=tried)
django.template.exceptions.TemplateDoesNotExist: base.html

The above exception was the direct cause of the following exception:

Traceback (most recent call last):
  File "/Library/Frameworks/Python.framework/Versions/3.6/lib/python3.6/site-packages/django/core/handlers/exception.py", line 35, in inner
    response = get_response(request)
  File "/Library/Frameworks/Python.framework/Versions/3.6/lib/python3.6/site-packages/django/core/handlers/base.py", line 128, in _get_response
    response = self.process_exception_by_middleware(e, request)
  File "/Library/Frameworks/Python.framework/Versions/3.6/lib/python3.6/site-packages/django/core/handlers/base.py", line 126, in _get_response
    response = wrapped_callback(request, *callback_args, **callback_kwargs)
  File "/Users/DengJ/Uranus/Work/WebDesign/Buybuybuy/super/views.py", line 26, in index
    return render(request,'super/index.html',locals())
  File "/Library/Frameworks/Python.framework/Versions/3.6/lib/python3.6/site-packages/django/shortcuts.py", line 36, in render
    content = loader.render_to_string(template_name, context, request, using=using)
  File "/Library/Frameworks/Python.framework/Versions/3.6/lib/python3.6/site-packages/django/template/loader.py", line 62, in render_to_string
    return template.render(context, request)
  File "/Library/Frameworks/Python.framework/Versions/3.6/lib/python3.6/site-packages/django/template/backends/django.py", line 63, in render
    reraise(exc, self.backend)
  File "/Library/Frameworks/Python.framework/Versions/3.6/lib/python3.6/site-packages/django/template/backends/django.py", line 84, in reraise
    raise new from exc
django.template.exceptions.TemplateDoesNotExist: base.html
ERROR 2018-11-26 15:46:44,338 /Library/Frameworks/Python.framework/Versions/3.6/lib/python3.6/site-packages/django/core/servers/basehttp.py basehttp.py basehttp log_message 124: "GET /index HTTP/1.1" 500 124012
ERROR 2018-11-26 15:55:22,243 /Library/Frameworks/Python.framework/Versions/3.6/lib/python3.6/site-packages/django/core/handlers/exception.py exception.py exception handle_uncaught_exception 118: Internal Server Error: /index
Traceback (most recent call last):
  File "/Library/Frameworks/Python.framework/Versions/3.6/lib/python3.6/site-packages/django/template/backends/django.py", line 61, in render
    return self.template.render(context)
  File "/Library/Frameworks/Python.framework/Versions/3.6/lib/python3.6/site-packages/django/template/base.py", line 175, in render
    return self._render(context)
  File "/Library/Frameworks/Python.framework/Versions/3.6/lib/python3.6/site-packages/django/template/base.py", line 167, in _render
    return self.nodelist.render(context)
  File "/Library/Frameworks/Python.framework/Versions/3.6/lib/python3.6/site-packages/django/template/base.py", line 943, in render
    bit = node.render_annotated(context)
  File "/Library/Frameworks/Python.framework/Versions/3.6/lib/python3.6/site-packages/django/template/base.py", line 910, in render_annotated
    return self.render(context)
  File "/Library/Frameworks/Python.framework/Versions/3.6/lib/python3.6/site-packages/django/template/loader_tags.py", line 132, in render
    compiled_parent = self.get_parent(context)
  File "/Library/Frameworks/Python.framework/Versions/3.6/lib/python3.6/site-packages/django/template/loader_tags.py", line 129, in get_parent
    return self.find_template(parent, context)
  File "/Library/Frameworks/Python.framework/Versions/3.6/lib/python3.6/site-packages/django/template/loader_tags.py", line 109, in find_template
    template_name, skip=history,
  File "/Library/Frameworks/Python.framework/Versions/3.6/lib/python3.6/site-packages/django/template/engine.py", line 130, in find_template
    raise TemplateDoesNotExist(name, tried=tried)
django.template.exceptions.TemplateDoesNotExist: base.html

The above exception was the direct cause of the following exception:

Traceback (most recent call last):
  File "/Library/Frameworks/Python.framework/Versions/3.6/lib/python3.6/site-packages/django/core/handlers/exception.py", line 35, in inner
    response = get_response(request)
  File "/Library/Frameworks/Python.framework/Versions/3.6/lib/python3.6/site-packages/django/core/handlers/base.py", line 128, in _get_response
    response = self.process_exception_by_middleware(e, request)
  File "/Library/Frameworks/Python.framework/Versions/3.6/lib/python3.6/site-packages/django/core/handlers/base.py", line 126, in _get_response
    response = wrapped_callback(request, *callback_args, **callback_kwargs)
  File "/Users/DengJ/Uranus/Work/WebDesign/Buybuybuy/super/views.py", line 26, in index
    return render(request,'super/index.html',locals())
  File "/Library/Frameworks/Python.framework/Versions/3.6/lib/python3.6/site-packages/django/shortcuts.py", line 36, in render
    content = loader.render_to_string(template_name, context, request, using=using)
  File "/Library/Frameworks/Python.framework/Versions/3.6/lib/python3.6/site-packages/django/template/loader.py", line 62, in render_to_string
    return template.render(context, request)
  File "/Library/Frameworks/Python.framework/Versions/3.6/lib/python3.6/site-packages/django/template/backends/django.py", line 63, in render
    reraise(exc, self.backend)
  File "/Library/Frameworks/Python.framework/Versions/3.6/lib/python3.6/site-packages/django/template/backends/django.py", line 84, in reraise
    raise new from exc
django.template.exceptions.TemplateDoesNotExist: base.html
ERROR 2018-11-26 15:55:22,426 /Library/Frameworks/Python.framework/Versions/3.6/lib/python3.6/site-packages/django/core/servers/basehttp.py basehttp.py basehttp log_message 124: "GET /index HTTP/1.1" 500 123917
ERROR 2018-11-26 16:02:20,579 /Library/Frameworks/Python.framework/Versions/3.6/lib/python3.6/site-packages/django/core/handlers/exception.py exception.py exception handle_uncaught_exception 118: Internal Server Error: /index
Traceback (most recent call last):
  File "/Library/Frameworks/Python.framework/Versions/3.6/lib/python3.6/site-packages/django/core/handlers/exception.py", line 35, in inner
    response = get_response(request)
  File "/Library/Frameworks/Python.framework/Versions/3.6/lib/python3.6/site-packages/django/core/handlers/base.py", line 128, in _get_response
    response = self.process_exception_by_middleware(e, request)
  File "/Library/Frameworks/Python.framework/Versions/3.6/lib/python3.6/site-packages/django/core/handlers/base.py", line 126, in _get_response
    response = wrapped_callback(request, *callback_args, **callback_kwargs)
  File "/Users/DengJ/Uranus/Work/WebDesign/Buybuybuy/super/views.py", line 26, in index
    return render(request,'super/index.html',locals())
  File "/Library/Frameworks/Python.framework/Versions/3.6/lib/python3.6/site-packages/django/shortcuts.py", line 36, in render
    content = loader.render_to_string(template_name, context, request, using=using)
  File "/Library/Frameworks/Python.framework/Versions/3.6/lib/python3.6/site-packages/django/template/loader.py", line 62, in render_to_string
    return template.render(context, request)
  File "/Library/Frameworks/Python.framework/Versions/3.6/lib/python3.6/site-packages/django/template/backends/django.py", line 61, in render
    return self.template.render(context)
  File "/Library/Frameworks/Python.framework/Versions/3.6/lib/python3.6/site-packages/django/template/base.py", line 175, in render
    return self._render(context)
  File "/Library/Frameworks/Python.framework/Versions/3.6/lib/python3.6/site-packages/django/template/base.py", line 167, in _render
    return self.nodelist.render(context)
  File "/Library/Frameworks/Python.framework/Versions/3.6/lib/python3.6/site-packages/django/template/base.py", line 943, in render
    bit = node.render_annotated(context)
  File "/Library/Frameworks/Python.framework/Versions/3.6/lib/python3.6/site-packages/django/template/base.py", line 910, in render_annotated
    return self.render(context)
  File "/Library/Frameworks/Python.framework/Versions/3.6/lib/python3.6/site-packages/django/template/loader_tags.py", line 155, in render
    return compiled_parent._render(context)
  File "/Library/Frameworks/Python.framework/Versions/3.6/lib/python3.6/site-packages/django/template/base.py", line 167, in _render
    return self.nodelist.render(context)
  File "/Library/Frameworks/Python.framework/Versions/3.6/lib/python3.6/site-packages/django/template/base.py", line 943, in render
    bit = node.render_annotated(context)
  File "/Library/Frameworks/Python.framework/Versions/3.6/lib/python3.6/site-packages/django/template/base.py", line 910, in render_annotated
    return self.render(context)
  File "/Library/Frameworks/Python.framework/Versions/3.6/lib/python3.6/site-packages/django/template/loader_tags.py", line 194, in render
    return template.render(context)
  File "/Library/Frameworks/Python.framework/Versions/3.6/lib/python3.6/site-packages/django/template/base.py", line 177, in render
    return self._render(context)
  File "/Library/Frameworks/Python.framework/Versions/3.6/lib/python3.6/site-packages/django/template/base.py", line 167, in _render
    return self.nodelist.render(context)
  File "/Library/Frameworks/Python.framework/Versions/3.6/lib/python3.6/site-packages/django/template/base.py", line 943, in render
    bit = node.render_annotated(context)
  File "/Library/Frameworks/Python.framework/Versions/3.6/lib/python3.6/site-packages/django/template/base.py", line 910, in render_annotated
    return self.render(context)
  File "/Library/Frameworks/Python.framework/Versions/3.6/lib/python3.6/site-packages/django/template/defaulttags.py", line 447, in render
    url = reverse(view_name, args=args, kwargs=kwargs, current_app=current_app)
  File "/Library/Frameworks/Python.framework/Versions/3.6/lib/python3.6/site-packages/django/urls/base.py", line 90, in reverse
    return iri_to_uri(resolver._reverse_with_prefix(view, prefix, *args, **kwargs))
  File "/Library/Frameworks/Python.framework/Versions/3.6/lib/python3.6/site-packages/django/urls/resolvers.py", line 636, in _reverse_with_prefix
    raise NoReverseMatch(msg)
django.urls.exceptions.NoReverseMatch: Reverse for 'siteswitch' not found. 'siteswitch' is not a valid view function or pattern name.
ERROR 2018-11-26 16:02:20,790 /Library/Frameworks/Python.framework/Versions/3.6/lib/python3.6/site-packages/django/core/servers/basehttp.py basehttp.py basehttp log_message 124: "GET /index HTTP/1.1" 500 159373
ERROR 2018-11-26 16:15:50,861 /Library/Frameworks/Python.framework/Versions/3.6/lib/python3.6/site-packages/django/core/handlers/exception.py exception.py exception handle_uncaught_exception 118: Internal Server Error: /index
Traceback (most recent call last):
  File "/Library/Frameworks/Python.framework/Versions/3.6/lib/python3.6/site-packages/django/core/handlers/exception.py", line 35, in inner
    response = get_response(request)
  File "/Library/Frameworks/Python.framework/Versions/3.6/lib/python3.6/site-packages/django/core/handlers/base.py", line 128, in _get_response
    response = self.process_exception_by_middleware(e, request)
  File "/Library/Frameworks/Python.framework/Versions/3.6/lib/python3.6/site-packages/django/core/handlers/base.py", line 126, in _get_response
    response = wrapped_callback(request, *callback_args, **callback_kwargs)
  File "/Users/DengJ/Uranus/Work/WebDesign/Buybuybuy/super/views.py", line 26, in index
    return render(request,'super/index.html',locals())
  File "/Library/Frameworks/Python.framework/Versions/3.6/lib/python3.6/site-packages/django/shortcuts.py", line 36, in render
    content = loader.render_to_string(template_name, context, request, using=using)
  File "/Library/Frameworks/Python.framework/Versions/3.6/lib/python3.6/site-packages/django/template/loader.py", line 62, in render_to_string
    return template.render(context, request)
  File "/Library/Frameworks/Python.framework/Versions/3.6/lib/python3.6/site-packages/django/template/backends/django.py", line 61, in render
    return self.template.render(context)
  File "/Library/Frameworks/Python.framework/Versions/3.6/lib/python3.6/site-packages/django/template/base.py", line 175, in render
    return self._render(context)
  File "/Library/Frameworks/Python.framework/Versions/3.6/lib/python3.6/site-packages/django/template/base.py", line 167, in _render
    return self.nodelist.render(context)
  File "/Library/Frameworks/Python.framework/Versions/3.6/lib/python3.6/site-packages/django/template/base.py", line 943, in render
    bit = node.render_annotated(context)
  File "/Library/Frameworks/Python.framework/Versions/3.6/lib/python3.6/site-packages/django/template/base.py", line 910, in render_annotated
    return self.render(context)
  File "/Library/Frameworks/Python.framework/Versions/3.6/lib/python3.6/site-packages/django/template/loader_tags.py", line 155, in render
    return compiled_parent._render(context)
  File "/Library/Frameworks/Python.framework/Versions/3.6/lib/python3.6/site-packages/django/template/base.py", line 167, in _render
    return self.nodelist.render(context)
  File "/Library/Frameworks/Python.framework/Versions/3.6/lib/python3.6/site-packages/django/template/base.py", line 943, in render
    bit = node.render_annotated(context)
  File "/Library/Frameworks/Python.framework/Versions/3.6/lib/python3.6/site-packages/django/template/base.py", line 910, in render_annotated
    return self.render(context)
  File "/Library/Frameworks/Python.framework/Versions/3.6/lib/python3.6/site-packages/django/template/loader_tags.py", line 194, in render
    return template.render(context)
  File "/Library/Frameworks/Python.framework/Versions/3.6/lib/python3.6/site-packages/django/template/base.py", line 177, in render
    return self._render(context)
  File "/Library/Frameworks/Python.framework/Versions/3.6/lib/python3.6/site-packages/django/template/base.py", line 167, in _render
    return self.nodelist.render(context)
  File "/Library/Frameworks/Python.framework/Versions/3.6/lib/python3.6/site-packages/django/template/base.py", line 943, in render
    bit = node.render_annotated(context)
  File "/Library/Frameworks/Python.framework/Versions/3.6/lib/python3.6/site-packages/django/template/base.py", line 910, in render_annotated
    return self.render(context)
  File "/Library/Frameworks/Python.framework/Versions/3.6/lib/python3.6/site-packages/django/template/defaulttags.py", line 447, in render
    url = reverse(view_name, args=args, kwargs=kwargs, current_app=current_app)
  File "/Library/Frameworks/Python.framework/Versions/3.6/lib/python3.6/site-packages/django/urls/base.py", line 90, in reverse
    return iri_to_uri(resolver._reverse_with_prefix(view, prefix, *args, **kwargs))
  File "/Library/Frameworks/Python.framework/Versions/3.6/lib/python3.6/site-packages/django/urls/resolvers.py", line 636, in _reverse_with_prefix
    raise NoReverseMatch(msg)
django.urls.exceptions.NoReverseMatch: Reverse for 'siteswitch' not found. 'siteswitch' is not a valid view function or pattern name.
ERROR 2018-11-26 16:15:50,964 /Library/Frameworks/Python.framework/Versions/3.6/lib/python3.6/site-packages/django/core/servers/basehttp.py basehttp.py basehttp log_message 124: "GET /index HTTP/1.1" 500 159391
ERROR 2018-11-26 16:18:20,111 /Library/Frameworks/Python.framework/Versions/3.6/lib/python3.6/site-packages/django/core/handlers/exception.py exception.py exception handle_uncaught_exception 118: Internal Server Error: /index
Traceback (most recent call last):
  File "/Library/Frameworks/Python.framework/Versions/3.6/lib/python3.6/site-packages/django/core/handlers/exception.py", line 35, in inner
    response = get_response(request)
  File "/Library/Frameworks/Python.framework/Versions/3.6/lib/python3.6/site-packages/django/core/handlers/base.py", line 128, in _get_response
    response = self.process_exception_by_middleware(e, request)
  File "/Library/Frameworks/Python.framework/Versions/3.6/lib/python3.6/site-packages/django/core/handlers/base.py", line 126, in _get_response
    response = wrapped_callback(request, *callback_args, **callback_kwargs)
  File "/Users/DengJ/Uranus/Work/WebDesign/Buybuybuy/super/views.py", line 26, in index
    return render(request,'super/index.html',locals())
  File "/Library/Frameworks/Python.framework/Versions/3.6/lib/python3.6/site-packages/django/shortcuts.py", line 36, in render
    content = loader.render_to_string(template_name, context, request, using=using)
  File "/Library/Frameworks/Python.framework/Versions/3.6/lib/python3.6/site-packages/django/template/loader.py", line 62, in render_to_string
    return template.render(context, request)
  File "/Library/Frameworks/Python.framework/Versions/3.6/lib/python3.6/site-packages/django/template/backends/django.py", line 61, in render
    return self.template.render(context)
  File "/Library/Frameworks/Python.framework/Versions/3.6/lib/python3.6/site-packages/django/template/base.py", line 175, in render
    return self._render(context)
  File "/Library/Frameworks/Python.framework/Versions/3.6/lib/python3.6/site-packages/django/template/base.py", line 167, in _render
    return self.nodelist.render(context)
  File "/Library/Frameworks/Python.framework/Versions/3.6/lib/python3.6/site-packages/django/template/base.py", line 943, in render
    bit = node.render_annotated(context)
  File "/Library/Frameworks/Python.framework/Versions/3.6/lib/python3.6/site-packages/django/template/base.py", line 910, in render_annotated
    return self.render(context)
  File "/Library/Frameworks/Python.framework/Versions/3.6/lib/python3.6/site-packages/django/template/loader_tags.py", line 155, in render
    return compiled_parent._render(context)
  File "/Library/Frameworks/Python.framework/Versions/3.6/lib/python3.6/site-packages/django/template/base.py", line 167, in _render
    return self.nodelist.render(context)
  File "/Library/Frameworks/Python.framework/Versions/3.6/lib/python3.6/site-packages/django/template/base.py", line 943, in render
    bit = node.render_annotated(context)
  File "/Library/Frameworks/Python.framework/Versions/3.6/lib/python3.6/site-packages/django/template/base.py", line 910, in render_annotated
    return self.render(context)
  File "/Library/Frameworks/Python.framework/Versions/3.6/lib/python3.6/site-packages/django/template/loader_tags.py", line 194, in render
    return template.render(context)
  File "/Library/Frameworks/Python.framework/Versions/3.6/lib/python3.6/site-packages/django/template/base.py", line 177, in render
    return self._render(context)
  File "/Library/Frameworks/Python.framework/Versions/3.6/lib/python3.6/site-packages/django/template/base.py", line 167, in _render
    return self.nodelist.render(context)
  File "/Library/Frameworks/Python.framework/Versions/3.6/lib/python3.6/site-packages/django/template/base.py", line 943, in render
    bit = node.render_annotated(context)
  File "/Library/Frameworks/Python.framework/Versions/3.6/lib/python3.6/site-packages/django/template/base.py", line 910, in render_annotated
    return self.render(context)
  File "/Library/Frameworks/Python.framework/Versions/3.6/lib/python3.6/site-packages/django/template/defaulttags.py", line 447, in render
    url = reverse(view_name, args=args, kwargs=kwargs, current_app=current_app)
  File "/Library/Frameworks/Python.framework/Versions/3.6/lib/python3.6/site-packages/django/urls/base.py", line 90, in reverse
    return iri_to_uri(resolver._reverse_with_prefix(view, prefix, *args, **kwargs))
  File "/Library/Frameworks/Python.framework/Versions/3.6/lib/python3.6/site-packages/django/urls/resolvers.py", line 636, in _reverse_with_prefix
    raise NoReverseMatch(msg)
django.urls.exceptions.NoReverseMatch: Reverse for 'siteswitch' not found. 'siteswitch' is not a valid view function or pattern name.
ERROR 2018-11-26 16:18:20,209 /Library/Frameworks/Python.framework/Versions/3.6/lib/python3.6/site-packages/django/core/servers/basehttp.py basehttp.py basehttp log_message 124: "GET /index HTTP/1.1" 500 159234
